OperationalError
sqlalchemy.exc.OperationalError: (sqlite3.OperationalError) no such column: table_fields.unique
[SQL: SELECT table_fields.id AS table_fields_id, table_fields.table_id AS table_fields_table_id, table_fields.name AS table_fields_name, table_fields.display_name AS table_fields_display_name, table_fields.field_type AS table_fields_field_type, table_fields.required AS table_fields_required, table_fields."unique" AS table_fields_unique, table_fields.options AS table_fields_options, table_fields."order" AS table_fields_order 
FROM table_fields 
WHERE table_fields.table_id = ? ORDER BY table_fields."order"]
[parameters: (2,)]
(Background on this error at: https://sqlalche.me/e/20/e3q8)

Traceback (most recent call last)
File "/home/runner/workspace/.pythonlibs/lib/python3.11/site-packages/sqlalchemy/engine/base.py", line 1964, in _exec_single_context
self.dialect.do_execute(
^
File "/home/runner/workspace/.pythonlibs/lib/python3.11/site-packages/sqlalchemy/engine/default.py", line 945, in do_execute
cursor.execute(statement, parameters)
^^^^^^^^^^^^^^^^^^^^^^^^^^^^^^^^^^^^^
The above exception was the direct cause of the following exception:
File "/home/runner/workspace/.pythonlibs/lib/python3.11/site-packages/flask/app.py", line 1536, in __call__
return self.wsgi_app(environ, start_response)
       ^^^^^^^^^^^^^^^^^^^^^^^^^^^^^^^^^^^^^^
File "/home/runner/workspace/.pythonlibs/lib/python3.11/site-packages/flask/app.py", line 1514, in wsgi_app
response = self.handle_exception(e)
           ^^^^^^^^^^^^^^^^^^^^^^^^
File "/home/runner/workspace/.pythonlibs/lib/python3.11/site-packages/flask/app.py", line 1511, in wsgi_app
response = self.full_dispatch_request()
           ^^^^^^^^^^^^^^^^^^^^^^^^^^^^
File "/home/runner/workspace/.pythonlibs/lib/python3.11/site-packages/flask/app.py", line 919, in full_dispatch_request
rv = self.handle_user_exception(e)
     ^^^^^^^^^^^^^^^^^^^^^^^^^^^^^
File "/home/runner/workspace/.pythonlibs/lib/python3.11/site-packages/flask/app.py", line 917, in full_dispatch_request
rv = self.dispatch_request()
     ^^^^^^^^^^^^^^^^^^^^^^^
File "/home/runner/workspace/.pythonlibs/lib/python3.11/site-packages/flask/app.py", line 902, in dispatch_request
return self.ensure_sync(self.view_functions[rule.endpoint])(**view_args)  # type: ignore[no-any-return]
       ^^^^^^^^^^^^^^^^^^^^^^^^^^^^^^^^^^^^^^^^^^^^^^^^^^^^^^^^^^^^^^^^^
File "/home/runner/workspace/.pythonlibs/lib/python3.11/site-packages/flask_login/utils.py", line 290, in decorated_view
return current_app.ensure_sync(func)(*args, **kwargs)
       ^^^^^^^^^^^^^^^^^^^^^^^^^^^^^^^^^^^^^^^^^^^^^^
File "/home/runner/workspace/routes.py", line 352, in table_records
fields = TableField.query.filter_by(table_id=table_id).order_by(TableField.order).all()
         ^^^^^^^^^^^^^^^^^^^^^^^^^^^^^^^^^^^^^^^^^^^^^^^^^^^^^^^^^^^^^^^^^^^^^^^^^^^^^^
File "/home/runner/workspace/.pythonlibs/lib/python3.11/site-packages/sqlalchemy/orm/query.py", line 2704, in all
return self._iter().all()  # type: ignore
       ^^^^^^^^^^^^
File "/home/runner/workspace/.pythonlibs/lib/python3.11/site-packages/sqlalchemy/orm/query.py", line 2858, in _iter
result: Union[ScalarResult[_T], Result[_T]] = self.session.execute(
                                              
File "/home/runner/workspace/.pythonlibs/lib/python3.11/site-packages/sqlalchemy/orm/session.py", line 2365, in execute
return self._execute_internal(
       
File "/home/runner/workspace/.pythonlibs/lib/python3.11/site-packages/sqlalchemy/orm/session.py", line 2251, in _execute_internal
result: Result[Any] = compile_state_cls.orm_execute_statement(
                      
File "/home/runner/workspace/.pythonlibs/lib/python3.11/site-packages/sqlalchemy/orm/context.py", line 306, in orm_execute_statement
result = conn.execute(
         
File "/home/runner/workspace/.pythonlibs/lib/python3.11/site-packages/sqlalchemy/engine/base.py", line 1416, in execute
return meth(
       
File "/home/runner/workspace/.pythonlibs/lib/python3.11/site-packages/sqlalchemy/sql/elements.py", line 523, in _execute_on_connection
return connection._execute_clauseelement(
       
File "/home/runner/workspace/.pythonlibs/lib/python3.11/site-packages/sqlalchemy/engine/base.py", line 1638, in _execute_clauseelement
ret = self._execute_context(
      
File "/home/runner/workspace/.pythonlibs/lib/python3.11/site-packages/sqlalchemy/engine/base.py", line 1843, in _execute_context
return self._exec_single_context(
       
File "/home/runner/workspace/.pythonlibs/lib/python3.11/site-packages/sqlalchemy/engine/base.py", line 1983, in _exec_single_context
self._handle_dbapi_exception(
^
File "/home/runner/workspace/.pythonlibs/lib/python3.11/site-packages/sqlalchemy/engine/base.py", line 2352, in _handle_dbapi_exception
raise sqlalchemy_exception.with_traceback(exc_info[2]) from e
^^^^^^^^^^^^^^^^^^^^^^^^^^^^^^^^^^^^^^^^^^^^^^^^^^^^^^^^^^^^^
File "/home/runner/workspace/.pythonlibs/lib/python3.11/site-packages/sqlalchemy/engine/base.py", line 1964, in _exec_single_context
self.dialect.do_execute(
^
File "/home/runner/workspace/.pythonlibs/lib/python3.11/site-packages/sqlalchemy/engine/default.py", line 945, in do_execute
cursor.execute(statement, parameters)
^^^^^^^^^^^^^^^^^^^^^^^^^^^^^^^^^^^^^
sqlalchemy.exc.OperationalError: (sqlite3.OperationalError) no such column: table_fields.unique
[SQL: SELECT table_fields.id AS table_fields_id, table_fields.table_id AS table_fields_table_id, table_fields.name AS table_fields_name, table_fields.display_name AS table_fields_display_name, table_fields.field_type AS table_fields_field_type, table_fields.required AS table_fields_required, table_fields."unique" AS table_fields_unique, table_fields.options AS table_fields_options, table_fields."order" AS table_fields_order
FROM table_fields
WHERE table_fields.table_id = ? ORDER BY table_fields."order"]
[parameters: (2,)]
(Background on this error at: https://sqlalche.me/e/20/e3q8)
The debugger caught an exception in your WSGI application. You can now look at the traceback which led to the error.
To switch between the interactive traceback and the plaintext one, you can click on the "Traceback" headline. From the text traceback you can also create a paste of it.

Brought to you by DON'T PANIC, your friendly Werkzeug powered traceback interpreter.